<?xml version="1.0"?>

<robot name="wheel" xmlns:xacro="http://www.ros.org/wiki/xacro">

<xacro:property name="wheel_radius" value="0.16" />
<xacro:property name="wheel_width"  value="0.1"  />
<xacro:property name="wheel_mass"   value="2.7"  />  <!-- in kg -->


   <!-- Macro for calculating inertia of cylindric wheel -->
   <xacro:macro name="wheel_inertia" params="m r h">
      <inertia ixx="${ m * ( 3 * r*r + h*h ) / 12}" ixy="0" ixz="0"
               iyy="${ m * ( 3 * r*r + h*h ) / 12}" iyz="0"
               izz="${ m * r / 2}" />
   </xacro:macro>


   <xacro:macro name="wheel" params="fb lr parent translateX translateY translateZ flipY">
     
   <!-- fb: front, back; lr: left right -->
      <link name="${fb}_${lr}_wheel">
         <visual>
            <origin xyz="0 0 0" rpy="${flipY*M_PI/2} 0 0"/>  <!-- make sure the wheel is in the correct position -->
            <geometry>
               <cylinder length="${wheel_width}" radius="${wheel_radius}" />
            </geometry>
            <material name="Black" />
         </visual>
         <collision>
            <origin xyz="0 0 0" rpy="${flipY*M_PI/2} 0 0"/>
            <geometry>
               <cylinder length="${wheel_width}" radius="${wheel_radius}" />
            </geometry>
         </collision>
         <inertial>
            <mass value="${wheel_mass}" />
            <origin xyz="0 0 0" />
            <wheel_inertia m="${wheel_mass}" r="${wheel_radius}" h="${wheel_width}" />
         </inertial>
      </link>
   

      <gazebo reference="${fb}_${lr}_wheel" >
         <mu1 value="1.0"/>
         <mu2 value="1.0" />
         <kp  value="10000000.0" />
         <kd  value="1.0" />
         <fdir1 value="1 0 0" />
         <material>Gazebo/Black</material>
         <turnGravityOff>false</turnGravityOff>  
      </gazebo>


      <joint name="${fb}_${lr}_wheel_joint" type="continuous">
         <parent link="${parent}"/>
         <child link="${fb}_${lr}_wheel" />
         <origin xyz="${translateX} ${translateY} ${translateZ}" rpy="0 0 0" />
         <limit effort="1000" velocity="1000" />
         <axis xyz="0 1 0" /> 
         <joint_properties damping="0.0" friction="0.0" />
         <type>transmission_interface/SimpleTransmission</type>
      </joint>


      <!-- Transmission is important to link the joint and the controller -->
      
      <transmission name="${fb}_${lr}_wheel_joint_trans" >
         <type>transmission_interface/SimpleTransmission</type>
         <joint name="${fb}_${lr}_wheel_joint">
            <hardwareInterface>hardware_interface/EffortJointInterface</hardwareInterface>
         </joint>
         <actuator name="${fb}_${lr}_wheel_joint_motor">
            <hardwareInterface>hardware_interface/EffortJointInterface</hardwareInterface>
            <mechanicalReduction>1</mechanicalReduction> <!-- It is not true: we uses motor with gearbox and ration of 75 -->
         </actuator>
      </transmission>
          
   </xacro:macro>


</robot>
